0it [00:00, ?it/s]2022-06-05 15:38:52,951 - distributed.protocol.core - CRITICAL - Failed to Serialize
Traceback (most recent call last):
  File "c:\Users\chiranjiv\.conda\envs\malware\lib\site-packages\distributed\protocol\core.py", line 118, in dumps
    frames[0] = msgpack.dumps(msg, default=_encode_default, use_bin_type=True)
  File "c:\Users\chiranjiv\.conda\envs\malware\lib\site-packages\msgpack\__init__.py", line 35, in packb
    return Packer(**kwargs).pack(o)
  File "msgpack/_packer.pyx", line 294, in msgpack._cmsgpack.Packer.pack
  File "msgpack/_packer.pyx", line 300, in msgpack._cmsgpack.Packer.pack
  File "msgpack/_packer.pyx", line 297, in msgpack._cmsgpack.Packer.pack
  File "msgpack/_packer.pyx", line 264, in msgpack._cmsgpack.Packer._pack
  File "msgpack/_packer.pyx", line 231, in msgpack._cmsgpack.Packer._pack
  File "msgpack/_packer.pyx", line 231, in msgpack._cmsgpack.Packer._pack
  File "msgpack/_packer.pyx", line 264, in msgpack._cmsgpack.Packer._pack
  File "msgpack/_packer.pyx", line 231, in msgpack._cmsgpack.Packer._pack
  File "msgpack/_packer.pyx", line 231, in msgpack._cmsgpack.Packer._pack
  File "msgpack/_packer.pyx", line 231, in msgpack._cmsgpack.Packer._pack
  File "msgpack/_packer.pyx", line 285, in msgpack._cmsgpack.Packer._pack
  File "c:\Users\chiranjiv\.conda\envs\malware\lib\site-packages\distributed\protocol\core.py", line 109, in _encode_default
    frames.extend(create_serialized_sub_frames(obj))
  File "c:\Users\chiranjiv\.conda\envs\malware\lib\site-packages\distributed\protocol\core.py", line 76, in create_serialized_sub_frames
    sub_header = msgpack.dumps(
  File "c:\Users\chiranjiv\.conda\envs\malware\lib\site-packages\msgpack\__init__.py", line 35, in packb
    return Packer(**kwargs).pack(o)
  File "msgpack/_packer.pyx", line 294, in msgpack._cmsgpack.Packer.pack
  File "msgpack/_packer.pyx", line 300, in msgpack._cmsgpack.Packer.pack
  File "msgpack/_packer.pyx", line 297, in msgpack._cmsgpack.Packer.pack
  File "msgpack/_packer.pyx", line 231, in msgpack._cmsgpack.Packer._pack
  File "msgpack/_packer.pyx", line 264, in msgpack._cmsgpack.Packer._pack
MemoryError
2022-06-05 15:38:53,039 - distributed.comm.utils - ERROR - 
Traceback (most recent call last):
  File "c:\Users\chiranjiv\.conda\envs\malware\lib\site-packages\distributed\comm\utils.py", line 53, in _to_frames
    return list(protocol.dumps(msg, **kwargs))
  File "c:\Users\chiranjiv\.conda\envs\malware\lib\site-packages\distributed\protocol\core.py", line 118, in dumps
    frames[0] = msgpack.dumps(msg, default=_encode_default, use_bin_type=True)
  File "c:\Users\chiranjiv\.conda\envs\malware\lib\site-packages\msgpack\__init__.py", line 35, in packb
    return Packer(**kwargs).pack(o)
  File "msgpack/_packer.pyx", line 294, in msgpack._cmsgpack.Packer.pack
  File "msgpack/_packer.pyx", line 300, in msgpack._cmsgpack.Packer.pack
  File "msgpack/_packer.pyx", line 297, in msgpack._cmsgpack.Packer.pack
  File "msgpack/_packer.pyx", line 264, in msgpack._cmsgpack.Packer._pack
  File "msgpack/_packer.pyx", line 231, in msgpack._cmsgpack.Packer._pack
  File "msgpack/_packer.pyx", line 231, in msgpack._cmsgpack.Packer._pack
  File "msgpack/_packer.pyx", line 264, in msgpack._cmsgpack.Packer._pack
  File "msgpack/_packer.pyx", line 231, in msgpack._cmsgpack.Packer._pack
  File "msgpack/_packer.pyx", line 231, in msgpack._cmsgpack.Packer._pack
  File "msgpack/_packer.pyx", line 231, in msgpack._cmsgpack.Packer._pack
  File "msgpack/_packer.pyx", line 285, in msgpack._cmsgpack.Packer._pack
  File "c:\Users\chiranjiv\.conda\envs\malware\lib\site-packages\distributed\protocol\core.py", line 109, in _encode_default
    frames.extend(create_serialized_sub_frames(obj))
  File "c:\Users\chiranjiv\.conda\envs\malware\lib\site-packages\distributed\protocol\core.py", line 76, in create_serialized_sub_frames
    sub_header = msgpack.dumps(
  File "c:\Users\chiranjiv\.conda\envs\malware\lib\site-packages\msgpack\__init__.py", line 35, in packb
    return Packer(**kwargs).pack(o)
  File "msgpack/_packer.pyx", line 294, in msgpack._cmsgpack.Packer.pack
  File "msgpack/_packer.pyx", line 300, in msgpack._cmsgpack.Packer.pack
  File "msgpack/_packer.pyx", line 297, in msgpack._cmsgpack.Packer.pack
  File "msgpack/_packer.pyx", line 231, in msgpack._cmsgpack.Packer._pack
  File "msgpack/_packer.pyx", line 264, in msgpack._cmsgpack.Packer._pack
MemoryError
2022-06-05 15:38:53,087 - distributed.batched - ERROR - Error in batched write
Traceback (most recent call last):
  File "c:\Users\chiranjiv\.conda\envs\malware\lib\site-packages\distributed\batched.py", line 94, in _background_send
    nbytes = yield self.comm.write(
  File "c:\Users\chiranjiv\.conda\envs\malware\lib\site-packages\tornado\gen.py", line 762, in run
    value = future.result()
  File "c:\Users\chiranjiv\.conda\envs\malware\lib\site-packages\distributed\comm\tcp.py", line 271, in write
    frames = await to_frames(
  File "c:\Users\chiranjiv\.conda\envs\malware\lib\site-packages\distributed\comm\utils.py", line 70, in to_frames
    return _to_frames()
  File "c:\Users\chiranjiv\.conda\envs\malware\lib\site-packages\distributed\comm\utils.py", line 53, in _to_frames
    return list(protocol.dumps(msg, **kwargs))
  File "c:\Users\chiranjiv\.conda\envs\malware\lib\site-packages\distributed\protocol\core.py", line 118, in dumps
    frames[0] = msgpack.dumps(msg, default=_encode_default, use_bin_type=True)
  File "c:\Users\chiranjiv\.conda\envs\malware\lib\site-packages\msgpack\__init__.py", line 35, in packb
    return Packer(**kwargs).pack(o)
  File "msgpack/_packer.pyx", line 294, in msgpack._cmsgpack.Packer.pack
  File "msgpack/_packer.pyx", line 300, in msgpack._cmsgpack.Packer.pack
  File "msgpack/_packer.pyx", line 297, in msgpack._cmsgpack.Packer.pack
  File "msgpack/_packer.pyx", line 264, in msgpack._cmsgpack.Packer._pack
  File "msgpack/_packer.pyx", line 231, in msgpack._cmsgpack.Packer._pack
  File "msgpack/_packer.pyx", line 231, in msgpack._cmsgpack.Packer._pack
  File "msgpack/_packer.pyx", line 264, in msgpack._cmsgpack.Packer._pack
  File "msgpack/_packer.pyx", line 231, in msgpack._cmsgpack.Packer._pack
  File "msgpack/_packer.pyx", line 231, in msgpack._cmsgpack.Packer._pack
  File "msgpack/_packer.pyx", line 231, in msgpack._cmsgpack.Packer._pack
  File "msgpack/_packer.pyx", line 285, in msgpack._cmsgpack.Packer._pack
  File "c:\Users\chiranjiv\.conda\envs\malware\lib\site-packages\distributed\protocol\core.py", line 109, in _encode_default
    frames.extend(create_serialized_sub_frames(obj))
  File "c:\Users\chiranjiv\.conda\envs\malware\lib\site-packages\distributed\protocol\core.py", line 76, in create_serialized_sub_frames
    sub_header = msgpack.dumps(
  File "c:\Users\chiranjiv\.conda\envs\malware\lib\site-packages\msgpack\__init__.py", line 35, in packb
    return Packer(**kwargs).pack(o)
  File "msgpack/_packer.pyx", line 294, in msgpack._cmsgpack.Packer.pack
  File "msgpack/_packer.pyx", line 300, in msgpack._cmsgpack.Packer.pack
  File "msgpack/_packer.pyx", line 297, in msgpack._cmsgpack.Packer.pack
  File "msgpack/_packer.pyx", line 231, in msgpack._cmsgpack.Packer._pack
  File "msgpack/_packer.pyx", line 264, in msgpack._cmsgpack.Packer._pack
MemoryError
2022-06-05 15:38:53,179 - tornado.application - ERROR - Exception in callback <bound method Client._heartbeat of <Client: 'tcp://127.0.0.1:62577' processes=4 threads=16, memory=7.42 GiB>>
Traceback (most recent call last):
  File "c:\Users\chiranjiv\.conda\envs\malware\lib\site-packages\tornado\ioloop.py", line 905, in _run
    return self.callback()
  File "c:\Users\chiranjiv\.conda\envs\malware\lib\site-packages\distributed\client.py", line 1343, in _heartbeat
    self.scheduler_comm.send({"op": "heartbeat-client"})
  File "c:\Users\chiranjiv\.conda\envs\malware\lib\site-packages\distributed\batched.py", line 137, in send
    raise CommClosedError(f"Comm {self.comm!r} already closed.")
distributed.comm.core.CommClosedError: Comm <TCP (closed) Client->Scheduler local=tcp://127.0.0.1:62622 remote=tcp://127.0.0.1:62577> already closed.
0it [03:02, ?it/s]
2022-06-05 15:38:53,519 - distributed.protocol.core - CRITICAL - Failed to Serialize
Traceback (most recent call last):
  File "c:\Users\chiranjiv\.conda\envs\malware\lib\site-packages\distributed\protocol\core.py", line 118, in dumps
    frames[0] = msgpack.dumps(msg, default=_encode_default, use_bin_type=True)
  File "c:\Users\chiranjiv\.conda\envs\malware\lib\site-packages\msgpack\__init__.py", line 35, in packb
    return Packer(**kwargs).pack(o)
  File "msgpack/_packer.pyx", line 120, in msgpack._cmsgpack.Packer.__cinit__
MemoryError: Unable to allocate internal buffer.
2022-06-05 15:38:53,567 - distributed.comm.utils - ERROR - Unable to allocate internal buffer.
Traceback (most recent call last):
  File "c:\Users\chiranjiv\.conda\envs\malware\lib\site-packages\distributed\comm\utils.py", line 53, in _to_frames
    return list(protocol.dumps(msg, **kwargs))
  File "c:\Users\chiranjiv\.conda\envs\malware\lib\site-packages\distributed\protocol\core.py", line 118, in dumps
    frames[0] = msgpack.dumps(msg, default=_encode_default, use_bin_type=True)
  File "c:\Users\chiranjiv\.conda\envs\malware\lib\site-packages\msgpack\__init__.py", line 35, in packb
    return Packer(**kwargs).pack(o)
  File "msgpack/_packer.pyx", line 120, in msgpack._cmsgpack.Packer.__cinit__
MemoryError: Unable to allocate internal buffer.
2022-06-05 15:38:54,223 - distributed.client - ERROR - Unable to allocate internal buffer.
Traceback (most recent call last):
  File "c:\Users\chiranjiv\.conda\envs\malware\lib\site-packages\distributed\comm\tcp.py", line 226, in read
    frames_nbytes = await stream.read_bytes(fmt_size)
tornado.iostream.StreamClosedError: Stream is closed

The above exception was the direct cause of the following exception:

Traceback (most recent call last):
  File "c:\Users\chiranjiv\.conda\envs\malware\lib\site-packages\distributed\client.py", line 1396, in _handle_report
    msgs = await self.scheduler_comm.comm.read()
  File "c:\Users\chiranjiv\.conda\envs\malware\lib\site-packages\distributed\comm\tcp.py", line 242, in read
    convert_stream_closed_error(self, e)
  File "c:\Users\chiranjiv\.conda\envs\malware\lib\site-packages\distributed\comm\tcp.py", line 150, in convert_stream_closed_error
    raise CommClosedError(f"in {obj}: {exc}") from exc
distributed.comm.core.CommClosedError: in <TCP (closed) Client->Scheduler local=tcp://127.0.0.1:62622 remote=tcp://127.0.0.1:62577>: Stream is closed

During handling of the above exception, another exception occurred:

Traceback (most recent call last):
  File "c:\Users\chiranjiv\.conda\envs\malware\lib\site-packages\distributed\utils.py", line 759, in wrapper
    return await func(*args, **kwargs)
  File "c:\Users\chiranjiv\.conda\envs\malware\lib\site-packages\distributed\client.py", line 1225, in _reconnect
    await self._ensure_connected(timeout=timeout)
  File "c:\Users\chiranjiv\.conda\envs\malware\lib\site-packages\distributed\client.py", line 1260, in _ensure_connected
    await asyncio.wait_for(self._update_scheduler_info(), timeout)
  File "c:\Users\chiranjiv\.conda\envs\malware\lib\asyncio\tasks.py", line 479, in wait_for
    return fut.result()
  File "c:\Users\chiranjiv\.conda\envs\malware\lib\site-packages\distributed\client.py", line 1307, in _update_scheduler_info
    self._scheduler_identity = SchedulerInfo(await self.scheduler.identity())
  File "c:\Users\chiranjiv\.conda\envs\malware\lib\site-packages\distributed\core.py", line 944, in send_recv_from_rpc
    return await send_recv(comm=comm, op=key, **kwargs)
  File "c:\Users\chiranjiv\.conda\envs\malware\lib\site-packages\distributed\core.py", line 706, in send_recv
    await comm.write(msg, serializers=serializers, on_error="raise")
  File "c:\Users\chiranjiv\.conda\envs\malware\lib\site-packages\distributed\comm\tcp.py", line 271, in write
    frames = await to_frames(
  File "c:\Users\chiranjiv\.conda\envs\malware\lib\site-packages\distributed\comm\utils.py", line 70, in to_frames
    return _to_frames()
  File "c:\Users\chiranjiv\.conda\envs\malware\lib\site-packages\distributed\comm\utils.py", line 53, in _to_frames
    return list(protocol.dumps(msg, **kwargs))
  File "c:\Users\chiranjiv\.conda\envs\malware\lib\site-packages\distributed\protocol\core.py", line 118, in dumps
    frames[0] = msgpack.dumps(msg, default=_encode_default, use_bin_type=True)
  File "c:\Users\chiranjiv\.conda\envs\malware\lib\site-packages\msgpack\__init__.py", line 35, in packb
    return Packer(**kwargs).pack(o)
  File "msgpack/_packer.pyx", line 120, in msgpack._cmsgpack.Packer.__cinit__
MemoryError: Unable to allocate internal buffer.
Unable to allocate internal buffer.
Traceback (most recent call last):
  File "c:\Users\chiranjiv\.conda\envs\malware\lib\site-packages\distributed\comm\tcp.py", line 226, in read
    frames_nbytes = await stream.read_bytes(fmt_size)
tornado.iostream.StreamClosedError: Stream is closed

The above exception was the direct cause of the following exception:

Traceback (most recent call last):
  File "c:\Users\chiranjiv\.conda\envs\malware\lib\site-packages\distributed\client.py", line 1396, in _handle_report
    msgs = await self.scheduler_comm.comm.read()
  File "c:\Users\chiranjiv\.conda\envs\malware\lib\site-packages\distributed\comm\tcp.py", line 242, in read
    convert_stream_closed_error(self, e)
  File "c:\Users\chiranjiv\.conda\envs\malware\lib\site-packages\distributed\comm\tcp.py", line 150, in convert_stream_closed_error
    raise CommClosedError(f"in {obj}: {exc}") from exc
distributed.comm.core.CommClosedError: in <TCP (closed) Client->Scheduler local=tcp://127.0.0.1:62622 remote=tcp://127.0.0.1:62577>: Stream is closed

During handling of the above exception, another exception occurred:

Traceback (most recent call last):
  File "c:\Users\chiranjiv\.conda\envs\malware\lib\site-packages\distributed\utils.py", line 759, in wrapper
    return await func(*args, **kwargs)
  File "c:\Users\chiranjiv\.conda\envs\malware\lib\site-packages\distributed\client.py", line 1404, in _handle_report
    await self._reconnect()
  File "c:\Users\chiranjiv\.conda\envs\malware\lib\site-packages\distributed\utils.py", line 759, in wrapper
    return await func(*args, **kwargs)
  File "c:\Users\chiranjiv\.conda\envs\malware\lib\site-packages\distributed\client.py", line 1225, in _reconnect
    await self._ensure_connected(timeout=timeout)
  File "c:\Users\chiranjiv\.conda\envs\malware\lib\site-packages\distributed\client.py", line 1260, in _ensure_connected
    await asyncio.wait_for(self._update_scheduler_info(), timeout)
  File "c:\Users\chiranjiv\.conda\envs\malware\lib\asyncio\tasks.py", line 479, in wait_for
    return fut.result()
  File "c:\Users\chiranjiv\.conda\envs\malware\lib\site-packages\distributed\client.py", line 1307, in _update_scheduler_info
    self._scheduler_identity = SchedulerInfo(await self.scheduler.identity())
  File "c:\Users\chiranjiv\.conda\envs\malware\lib\site-packages\distributed\core.py", line 944, in send_recv_from_rpc
    return await send_recv(comm=comm, op=key, **kwargs)
  File "c:\Users\chiranjiv\.conda\envs\malware\lib\site-packages\distributed\core.py", line 706, in send_recv
    await comm.write(msg, serializers=serializers, on_error="raise")
  File "c:\Users\chiranjiv\.conda\envs\malware\lib\site-packages\distributed\comm\tcp.py", line 271, in write
    frames = await to_frames(
  File "c:\Users\chiranjiv\.conda\envs\malware\lib\site-packages\distributed\comm\utils.py", line 70, in to_frames
    return _to_frames()
  File "c:\Users\chiranjiv\.conda\envs\malware\lib\site-packages\distributed\comm\utils.py", line 53, in _to_frames
    return list(protocol.dumps(msg, **kwargs))
  File "c:\Users\chiranjiv\.conda\envs\malware\lib\site-packages\distributed\protocol\core.py", line 118, in dumps
    frames[0] = msgpack.dumps(msg, default=_encode_default, use_bin_type=True)
  File "c:\Users\chiranjiv\.conda\envs\malware\lib\site-packages\msgpack\__init__.py", line 35, in packb
    return Packer(**kwargs).pack(o)
  File "msgpack/_packer.pyx", line 120, in msgpack._cmsgpack.Packer.__cinit__
MemoryError: Unable to allocate internal buffer.
2022-06-05 15:38:57,915 - distributed.protocol.core - CRITICAL - Failed to Serialize
Traceback (most recent call last):
  File "c:\Users\chiranjiv\.conda\envs\malware\lib\site-packages\distributed\protocol\core.py", line 118, in dumps
    frames[0] = msgpack.dumps(msg, default=_encode_default, use_bin_type=True)
  File "c:\Users\chiranjiv\.conda\envs\malware\lib\site-packages\msgpack\__init__.py", line 35, in packb
    return Packer(**kwargs).pack(o)
  File "msgpack/_packer.pyx", line 120, in msgpack._cmsgpack.Packer.__cinit__
MemoryError: Unable to allocate internal buffer.
2022-06-05 15:38:58,108 - distributed.comm.utils - ERROR - Unable to allocate internal buffer.
Traceback (most recent call last):
  File "c:\Users\chiranjiv\.conda\envs\malware\lib\site-packages\distributed\comm\utils.py", line 53, in _to_frames
    return list(protocol.dumps(msg, **kwargs))
  File "c:\Users\chiranjiv\.conda\envs\malware\lib\site-packages\distributed\protocol\core.py", line 118, in dumps
    frames[0] = msgpack.dumps(msg, default=_encode_default, use_bin_type=True)
  File "c:\Users\chiranjiv\.conda\envs\malware\lib\site-packages\msgpack\__init__.py", line 35, in packb
    return Packer(**kwargs).pack(o)
  File "msgpack/_packer.pyx", line 120, in msgpack._cmsgpack.Packer.__cinit__
MemoryError: Unable to allocate internal buffer.
2022-06-05 15:38:58,372 - tornado.application - ERROR - Exception in callback functools.partial(<function TCPServer._handle_connection.<locals>.<lambda> at 0x00000237A6C7FB80>, <Task finished name='Task-109' coro=<BaseTCPListener._handle_stream() done, defined at c:\Users\chiranjiv\.conda\envs\malware\lib\site-packages\distributed\comm\tcp.py:543> exception=MemoryError('Unable to allocate internal buffer.')>)
Traceback (most recent call last):
  File "c:\Users\chiranjiv\.conda\envs\malware\lib\site-packages\tornado\ioloop.py", line 741, in _run_callback
    ret = callback()
  File "c:\Users\chiranjiv\.conda\envs\malware\lib\site-packages\tornado\tcpserver.py", line 331, in <lambda>
    gen.convert_yielded(future), lambda f: f.result()
  File "c:\Users\chiranjiv\.conda\envs\malware\lib\site-packages\distributed\comm\tcp.py", line 560, in _handle_stream
    await self.comm_handler(comm)
  File "c:\Users\chiranjiv\.conda\envs\malware\lib\site-packages\distributed\core.py", line 573, in handle_comm
    await comm.write(result, serializers=serializers)
  File "c:\Users\chiranjiv\.conda\envs\malware\lib\site-packages\distributed\comm\tcp.py", line 271, in write
    frames = await to_frames(
  File "c:\Users\chiranjiv\.conda\envs\malware\lib\site-packages\distributed\comm\utils.py", line 70, in to_frames
    return _to_frames()
  File "c:\Users\chiranjiv\.conda\envs\malware\lib\site-packages\distributed\comm\utils.py", line 53, in _to_frames
    return list(protocol.dumps(msg, **kwargs))
  File "c:\Users\chiranjiv\.conda\envs\malware\lib\site-packages\distributed\protocol\core.py", line 118, in dumps
    frames[0] = msgpack.dumps(msg, default=_encode_default, use_bin_type=True)
  File "c:\Users\chiranjiv\.conda\envs\malware\lib\site-packages\msgpack\__init__.py", line 35, in packb
    return Packer(**kwargs).pack(o)
  File "msgpack/_packer.pyx", line 120, in msgpack._cmsgpack.Packer.__cinit__
MemoryError: Unable to allocate internal buffer.
